Workbook

Sheet _I
A1: Секції КВЕД | B1: назва секції КВЕД | C1: Критерії групування інформації за обсягом із розподілом по платниках (згідно поданої звітності) | D1: перша група | H1: друга група | L1: третя група (фізичні особи - підприємці) | AA1: 1200000 | AH1: 8300000 | AO1: 8300000
L2: платники з реєстрацією ПДВ | P2: платники без реєстрації ПДВ | T2: 2 група | U2: 2 група | V2: 2 група | W2: 2 група | X2: 2 група | Y2: 2 група | AA2: 1 група | AB2: 1 група | AC2: 1 група | AD2: 1 група | AE2: 1 група | AF2: 1 група | AH2: 3 група з ПДВ | AI2: 3 група з ПДВ | AJ2: 3 група з ПДВ | AK2: 3 група з ПДВ | AL2: 3 група з ПДВ | AM2: 3 група з ПДВ | AO2: 3 група без ПДВ | AP2: 3 група без ПДВ | AQ2: 3 група без ПДВ | AR2: 3 група без ПДВ | AS2: 3 група без ПДВ | AT2: 3 група без ПДВ | AW2: tech | AX2: tech
D3: кількість | E3: Обсяг доходу, (F01033, F01034) (код рядка 08), тис.грн. | F3: Надходження єдиного податку (1805), (станом на 01.01.2025) тис.грн. | G3: Надходження військового збору (11011700), (станом на 01.01.2025) тис.грн. | H3: кількість | I3: Обсяг доходу, (F01033, F01034) (код рядка 08), тис.грн. | J3: Надходження єдиного податку (1805), (станом на 01.01.2025) тис.грн. | K3: Надходження військового збору (11011700), (станом на 01.01.2025) тис.грн. | L3: кількість | M3: Обсяг доходу, (F01033, F01034) (код рядка 08), тис.грн. | N3: Надходження єдиного податку (1805), (станом на 01.01.2025) тис.грн. | O3: Надходження військового збору (11011700), (станом на 01.01.2025) тис.грн. | P3: кількість | Q3: Обсяг доходу, (F01033, F01034) (код рядка 08), тис.грн. | R3: Надходження єдиного податку (1805), (станом на 01.01.2025) тис.грн. | S3: Надходження військового збору (11011700), (станом на 01.01.2025) тис.грн. | T3: зміна кількості фопів | U3: ФОП-ів теоретично | V3: Середня виручка, тис грн | W3: Сумарна виручка в теорії | X3: Виручка на практиці | Y3: Аномалія понад нормою | AA3: =T3 -> зміна кількості фопів | AB3: =U3 -> ФОП-ів теоретично | AC3: =V3 -> Середня виручка, тис грн | AD3: =W3 -> Сумарна виручка в теорії | AE3: =X3 -> Виручка на практиці | AF3: =Y3 -> Аномалія понад нормою | AH3: =AA3 -> зміна кількості фопів | AI3: =AB3 -> ФОП-ів теоретично | AJ3: =AC3 -> Середня виручка, тис грн | AK3: =AD3 -> Сумарна виручка в теорії | AL3: =AE3 -> Виручка на практиці | AM3: =AF3 -> Аномалія понад нормою | AO3: =AH3 -> зміна кількості фопів | AP3: =AI3 -> ФОП-ів теоретично | AQ3: =AJ3 -> Середня виручка, тис грн | AR3: =AK3 -> Сумарна виручка в теорії | AS3: =AL3 -> Виручка на практиці | AT3: =AM3 -> Аномалія понад нормою | AW3: Нижн межа групи | AX3: Верхня межа групи
A4: _I | B4: Тимчасове розмiщування й органiзацiя харчування | C4: від 0 грн. до 49999,99 грн. | D4: 32 | E4: 302.27 | F4: 79.18391 | G4: 0 | H4: 3157 | I4: 21100.807 | J4: 29114.004 | K4: 105.21 | L4: 8 | M4: 0 | N4: 5.23987 | O4: 0 | P4: 2677 | Q4: 17406.319 | R4: 8589.8798 | S4: 5.6 | AE4: =SUMIFS(E4:E10000,$AX$4:$AX$10000,"<="&AA1) -> 0 | AF4: =SUMIFS(AF9:AF100000,AF9:AF100000,">0") -> 0 | AG4: Total | AL4: =SUMIFS(M4:M10000,$AX$4:$AX$10000,"<="&AH1) -> 0 | AM4: =SUMIFS(AM9:AM100000,AM9:AM100000,">0") -> 0 | AN4: Total | AS4: =SUMIFS(Q4:Q10000,$AX$4:$AX$10000,"<="&AO1) -> 0 | AT4: =SUMIFS(AT9:AT100000,AT9:AT100000,">0") -> 0 | AW4: =--MID(C4,FIND("від",C4)+4,FIND("грн",C4,FIND("від",C4))-FIND("від",C4)-4) -> 0 | AX4: =--MID(C4,FIND("до",C4)+3,FIND("грн",C4,FIND("до",C4))-FIND("до",C4)-3) -> #VALUE!
A5: _I | B5: Тимчасове розмiщування й органiзацiя харчування | C5: від 50000 грн. до 99999,99 грн. | D5: 14 | E5: 1067.251 | F5: 46.50105 | G5: 0 | H5: 726 | I5: 54913.364 | J5: 7452.856 | K5: 28.77 | L5: 3 | M5: 204.76609 | N5: 89.24549 | O5: 0 | P5: 419 | Q5: 30999.746 | R5: 1589.3481 | S5: 0.446 | AF5: =AF4/AE4 -> #DIV/0! | AG5: abuse index | AM5: =AM4/AL4 -> #DIV/0! | AN5: abuse index | AT5: =AT4/AS4 -> #DIV/0! | AW5: =--MID(C5,FIND("від",C5)+4,FIND("грн",C5,FIND("від",C5))-FIND("від",C5)-4) -> 50000 | AX5: =--MID(C5,FIND("до",C5)+3,FIND("грн",C5,FIND("до",C5))-FIND("до",C5)-3) -> #VALUE!
A6: _I | B6: Тимчасове розмiщування й органiзацiя харчування | C6: від 100000 грн. до 149999,99 грн. | D6: 17 | E6: 2042.0975 | F6: 62.48876 | G6: 0 | H6: 608 | I6: 75389.824 | J6: 6655.2211 | K6: 45.4 | L6: 1 | M6: 101.26252 | N6: 0.715 | O6: 0 | P6: 327 | Q6: 40327.137 | R6: 2593.1681 | S6: 0 | AW6: =--MID(C6,FIND("від",C6)+4,FIND("грн",C6,FIND("від",C6))-FIND("від",C6)-4) -> 100000 | AX6: =--MID(C6,FIND("до",C6)+3,FIND("грн",C6,FIND("до",C6))-FIND("до",C6)-3) -> #VALUE!
A7: _I | B7: Тимчасове розмiщування й органiзацiя харчування | C7: від 150000 грн. до 199999,99 грн. | D7: 6 | E7: 983.891 | F7: 21.3693 | G7: 0 | H7: 556 | I7: 97085.863 | J7: 6081.0272 | K7: 29.39 | L7: 1 | M7: 171.025 | N7: 13.33989 | O7: 0 | P7: 256 | Q7: 44386.64 | R7: 2327.5756 | S7: 0 | AW7: =--MID(C7,FIND("від",C7)+4,FIND("грн",C7,FIND("від",C7))-FIND("від",C7)-4) -> 150000 | AX7: =--MID(C7,FIND("до",C7)+3,FIND("грн",C7,FIND("до",C7))-FIND("до",C7)-3) -> #VALUE!
A8: _I | B8: Тимчасове розмiщування й органiзацiя харчування | C8: від 200000 грн. до 249999,99 грн. | D8: 5 | E8: 1144.8 | F8: 14.29493 | G8: 0 | H8: 594 | I8: 133246.38 | J8: 7199.2396 | K8: 35.25 | L8: 1 | M8: 216.51233 | N8: 8.33416 | O8: 0 | P8: 210 | Q8: 47049.983 | R8: 2251.4621 | S8: 0 | AW8: =--MID(C8,FIND("від",C8)+4,FIND("грн",C8,FIND("від",C8))-FIND("від",C8)-4) -> 200000 | AX8: =--MID(C8,FIND("до",C8)+3,FIND("грн",C8,FIND("до",C8))-FIND("до",C8)-3) -> #VALUE!
A9: _I | B9: Тимчасове розмiщування й органiзацiя харчування | C9: від 250000 грн. до 299999,99 грн. | D9: 7 | E9: 1840.053 | F9: 25.18017 | G9: 0 | H9: 571 | I9: 156493.92 | J9: 6799.1831 | K9: 33.92 | P9: 189 | Q9: 51603.544 | R9: 2352.577 | S9: 0 | T9: =AVERAGE(H5:H9)-AVERAGE(H10:H14) -> 151.6 | AA9: =IFERROR(AVERAGE(D5:D9)-AVERAGE(D10:D14),"-") -> 7 | AH9: =IFERROR(AVERAGE(L5:L9)-AVERAGE(L10:L14),"-") -> -0.5 | AO9: =AVERAGE(P5:P9)-AVERAGE(P10:P14) -> 150.8 | AW9: =--MID(C9,FIND("від",C9)+4,FIND("грн",C9,FIND("від",C9))-FIND("від",C9)-4) -> 250000 | AX9: =--MID(C9,FIND("до",C9)+3,FIND("грн",C9,FIND("до",C9))-FIND("до",C9)-3) -> #VALUE!
A10: _I | B10: Тимчасове розмiщування й органiзацiя харчування | C10: від 300000 грн. до 349999,99 грн. | D10: 3 | E10: 913.65 | F10: 9.4732 | G10: 0 | H10: 470 | I10: 151714.72 | J10: 5624.5012 | K10: 20.161 | L10: 3 | M10: 1026.9205 | N10: 48.4311 | O10: 0 | P10: 143 | Q10: 46343.981 | R10: 2305.0997 | S10: 0 | T10: =AVERAGE(H6:H10)-AVERAGE(H11:H15) -> 106.2 | AA10: =IFERROR(AVERAGE(D6:D10)-AVERAGE(D11:D15),"-") -> 5 | AH10: =IFERROR(AVERAGE(L6:L10)-AVERAGE(L11:L15),"-") -> 0.5 | AO10: =AVERAGE(P6:P10)-AVERAGE(P11:P15) -> 100 | AW10: =--MID(C10,FIND("від",C10)+4,FIND("грн",C10,FIND("від",C10))-FIND("від",C10)-4) -> 300000 | AX10: =--MID(C10,FIND("до",C10)+3,FIND("грн",C10,FIND("до",C10))-FIND("до",C10)-3) -> #VALUE!
A11: _I | B11: Тимчасове розмiщування й органiзацiя харчування | C11: від 350000 грн. до 399999,99 грн. | D11: 3 | E11: 1133.795 | F11: 6.6233 | G11: 0 | H11: 508 | I11: 189711.29 | J11: 6293.131 | K11: 28.66 | P11: 141 | Q11: 52805.888 | R11: 2216.3821 | S11: 0.285 | T11: =AVERAGE(H7:H11)-AVERAGE(H12:H16) -> 104.4 | AA11: =IFERROR(AVERAGE(D7:D11)-AVERAGE(D12:D16),"-") -> 2 | AH11: =IFERROR(AVERAGE(L7:L11)-AVERAGE(L12:L16),"-") -> 0.66666667 | AO11: =AVERAGE(P7:P11)-AVERAGE(P12:P16) -> 72.8 | AW11: =--MID(C11,FIND("від",C11)+4,FIND("грн",C11,FIND("від",C11))-FIND("від",C11)-4) -> 350000 | AX11: =--MID(C11,FIND("до",C11)+3,FIND("грн",C11,FIND("до",C11))-FIND("до",C11)-3) -> #VALUE!
A12: _I | B12: Тимчасове розмiщування й органiзацiя харчування | C12: від 400000 грн. до 449999,99 грн. | D12: 3 | E12: 1269 | F12: 10.813 | G12: 0 | H12: 442 | I12: 187254.03 | J12: 5415.0621 | K12: 34.46 | L12: 1 | M12: 413.697 | N12: 16.247 | O12: 0 | P12: 140 | Q12: 59377.876 | R12: 2812.2328 | S12: 3.511 | T12: =AVERAGE(H8:H12)-AVERAGE(H13:H17) -> 98.8 | AA12: =IFERROR(AVERAGE(D8:D12)-AVERAGE(D13:D17),"-") -> 1.6 | AH12: =IFERROR(AVERAGE(L8:L12)-AVERAGE(L13:L17),"-") -> - | AO12: =AVERAGE(P8:P12)-AVERAGE(P13:P17) -> 58.2 | AW12: =--MID(C12,FIND("від",C12)+4,FIND("грн",C12,FIND("від",C12))-FIND("від",C12)-4) -> 400000 | AX12: =--MID(C12,FIND("до",C12)+3,FIND("грн",C12,FIND("до",C12))-FIND("до",C12)-3) -> #VALUE!
A13: _I | B13: Тимчасове розмiщування й органiзацiя харчування | C13: від 450000 грн. до 499999,99 грн. | D13: 1 | E13: 495 | F13: 3.057 | G13: 0 | H13: 432 | I13: 204846.35 | J13: 5398.2583 | K13: 24.57495 | P13: 123 | Q13: 58365.386 | R13: 2874.6692 | S13: 2.13 | T13: =AVERAGE(H9:H13)-AVERAGE(H14:H18) -> 76.8 | AA13: =IFERROR(AVERAGE(D9:D13)-AVERAGE(D14:D18),"-") -> 0.4 | AH13: =IFERROR(AVERAGE(L9:L13)-AVERAGE(L14:L18),"-") -> - | AO13: =AVERAGE(P9:P13)-AVERAGE(P14:P18) -> 46.4 | AW13: =--MID(C13,FIND("від",C13)+4,FIND("грн",C13,FIND("від",C13))-FIND("від",C13)-4) -> 450000 | AX13: =--MID(C13,FIND("до",C13)+3,FIND("грн",C13,FIND("до",C13))-FIND("до",C13)-3) -> #VALUE!
A14: _I | B14: Тимчасове розмiщування й органiзацiя харчування | C14: від 500000 грн. до 549999,99 грн. | D14: 4 | E14: 2114.432 | F14: 13.10244 | G14: 0 | H14: 445 | I14: 233096.71 | J14: 5690.2369 | K14: 23.145 | P14: 100 | Q14: 52153.987 | R14: 2379.2148 | S14: 0 | T14: =AVERAGE(H10:H14)-AVERAGE(H15:H19) -> 74.2 | AA14: =IFERROR(AVERAGE(D10:D14)-AVERAGE(D15:D19),"-") -> 0 | AH14: =IFERROR(AVERAGE(L10:L14)-AVERAGE(L15:L19),"-") -> 1 | AO14: =AVERAGE(P10:P14)-AVERAGE(P15:P19) -> 33.4 | AW14: =--MID(C14,FIND("від",C14)+4,FIND("грн",C14,FIND("від",C14))-FIND("від",C14)-4) -> 500000 | AX14: =--MID(C14,FIND("до",C14)+3,FIND("грн",C14,FIND("до",C14))-FIND("до",C14)-3) -> #VALUE!
A15: _I | B15: Тимчасове розмiщування й органiзацiя харчування | C15: від 550000 грн. до 599999,99 грн. | D15: 2 | E15: 1115.28 | F15: 6.2336 | G15: 0 | H15: 441 | I15: 253625.06 | J15: 5733.3164 | K15: 38.1 | P15: 121 | Q15: 69362.329 | R15: 2921.012 | S15: 0 | T15: =AVERAGE(H11:H15)-AVERAGE(H16:H20) -> 84 | AA15: =IFERROR(AVERAGE(D11:D15)-AVERAGE(D16:D20),"-") -> -0.2 | AH15: =IFERROR(AVERAGE(L11:L15)-AVERAGE(L16:L20),"-") -> 0 | AO15: =AVERAGE(P11:P15)-AVERAGE(P16:P20) -> 40.4 | AW15: =--MID(C15,FIND("від",C15)+4,FIND("грн",C15,FIND("від",C15))-FIND("від",C15)-4) -> 550000 | AX15: =--MID(C15,FIND("до",C15)+3,FIND("грн",C15,FIND("до",C15))-FIND("до",C15)-3) -> #VALUE!
A16: _I | B16: Тимчасове розмiщування й органiзацiя харчування | C16: від 600000 грн. до 649999,99 грн. | D16: 4 | E16: 2463.223 | F16: 13.0222 | G16: 0 | H16: 417 | I16: 260911.46 | J16: 5511.5738 | K16: 28.15 | P16: 91 | Q16: 56805.475 | R16: 3029.3927 | S16: 0.8 | T16: =AVERAGE(H12:H16)-AVERAGE(H17:H21) -> 77.2 | AA16: =IFERROR(AVERAGE(D12:D16)-AVERAGE(D17:D21),"-") -> -0.2 | AH16: =IFERROR(AVERAGE(L12:L16)-AVERAGE(L17:L21),"-") -> 0 | AO16: =AVERAGE(P12:P16)-AVERAGE(P17:P21) -> 33.8 | AW16: =--MID(C16,FIND("від",C16)+4,FIND("грн",C16,FIND("від",C16))-FIND("від",C16)-4) -> 600000 | AX16: =--MID(C16,FIND("до",C16)+3,FIND("грн",C16,FIND("до",C16))-FIND("до",C16)-3) -> #VALUE!
A17: _I | B17: Тимчасове розмiщування й органiзацiя харчування | C17: від 650000 грн. до 699999,99 грн. | D17: 2 | E17: 1348.42 | F17: 10.6124 | G17: 0 | H17: 356 | I17: 240164.79 | J17: 4334.4037 | K17: 20.6 | P17: 97 | Q17: 65532.087 | R17: 3098.1679 | S17: 0 | T17: =AVERAGE(H13:H17)-AVERAGE(H18:H22) -> 50.8 | AA17: =IFERROR(AVERAGE(D13:D17)-AVERAGE(D18:D22),"-") -> -1.4 | AB17: =AVERAGE(D13:D17) -> 2.6 | AC17: =AVERAGE(AW17:AX17)/1000 -> #VALUE! | AD17: =IF(AA17<-0.4,AB17*AC17,0) -> #VALUE! | AE17: =IF(AD17=0,0,E17) -> #VALUE! | AF17: =IFERROR(AE17-AD17,0) -> 0 | AH17: =IFERROR(AVERAGE(L13:L17)-AVERAGE(L18:L22),"-") -> - | AO17: =AVERAGE(P13:P17)-AVERAGE(P18:P22) -> 29.6 | AW17: =--MID(C17,FIND("від",C17)+4,FIND("грн",C17,FIND("від",C17))-FIND("від",C17)-4) -> 650000 | AX17: =--MID(C17,FIND("до",C17)+3,FIND("грн",C17,FIND("до",C17))-FIND("до",C17)-3) -> #VALUE!
A18: _I | B18: Тимчасове розмiщування й органiзацiя харчування | C18: від 700000 грн. до 749999,99 грн. | D18: 3 | E18: 2156.7 | F18: 11.685 | G18: 0 | H18: 380 | I18: 275873.81 | J18: 5036.6654 | K18: 25.96554 | P18: 95 | Q18: 68803.91 | R18: 2930.1633 | S18: 0 | T18: =AVERAGE(H14:H18)-AVERAGE(H19:H23) -> 42.8 | AA18: =IFERROR(AVERAGE(D14:D18)-AVERAGE(D19:D23),"-") -> -2 | AB18: =AB17 -> 2.6 | AC18: =AVERAGE(AW18:AX18)/1000 -> #VALUE! | AD18: =IF(AA18<-0.4,AB18*AC18,0) -> #VALUE! | AE18: =IF(AD18=0,0,E18) -> #VALUE! | AF18: =IFERROR(AE18-AD18,0) -> 0 | AG18: =AC18-AC17 -> #VALUE! | AH18: =IFERROR(AVERAGE(L14:L18)-AVERAGE(L19:L23),"-") -> - | AO18: =AVERAGE(P14:P18)-AVERAGE(P19:P23) -> 31.8 | AW18: =--MID(C18,FIND("від",C18)+4,FIND("грн",C18,FIND("від",C18))-FIND("від",C18)-4) -> 700000 | AX18: =--MID(C18,FIND("до",C18)+3,FIND("грн",C18,FIND("до",C18))-FIND("до",C18)-3) -> #VALUE!
A19: _I | B19: Тимчасове розмiщування й органiзацiя харчування | C19: від 750000 грн. до 799999,99 грн. | D19: 3 | E19: 2320.7454 | F19: 10.5408 | G19: 0 | H19: 332 | I19: 257258.58 | J19: 4504.2701 | K19: 22.82 | L19: 1 | M19: 799.71442 | N19: 27.41 | O19: 0 | P19: 76 | Q19: 58828.334 | R19: 2773.6022 | S19: 0 | T19: =AVERAGE(H15:H19)-AVERAGE(H20:H24) -> 17.6 | AA19: =IFERROR(AVERAGE(D15:D19)-AVERAGE(D20:D24),"-") -> -2.7 | AB19: =AB18 -> 2.6 | AC19: =AVERAGE(AW19:AX19)/1000 -> #VALUE! | AD19: =IF(AA19<-0.4,AB19*AC19,0) -> #VALUE! | AE19: =IF(AD19=0,0,E19) -> #VALUE! | AF19: =IFERROR(AE19-AD19,0) -> 0 | AG19: =AC19-AC18 -> #VALUE! | AH19: =IFERROR(AVERAGE(L15:L19)-AVERAGE(L20:L24),"-") -> - | AO19: =AVERAGE(P15:P19)-AVERAGE(P20:P24) -> 26 | AW19: =--MID(C19,FIND("від",C19)+4,FIND("грн",C19,FIND("від",C19))-FIND("від",C19)-4) -> 750000 | AX19: =--MID(C19,FIND("до",C19)+3,FIND("грн",C19,FIND("до",C19))-FIND("до",C19)-3) -> #VALUE!
A20: _I | B20: Тимчасове розмiщування й органiзацiя харчування | C20: від 800000 грн. до 849999,99 грн. | D20: 2 | E20: 1606.245 | F20: 6.9668 | G20: 0.8 | H20: 363 | I20: 298818.58 | J20: 4746.0294 | K20: 34.8706 | P20: 64 | Q20: 53021.142 | R20: 2352.8118 | S20: 0.71 | T20: =AVERAGE(H16:H20)-AVERAGE(H21:H25) -> 12 | AA20: =IFERROR(AVERAGE(D16:D20)-AVERAGE(D21:D25),"-") -> -2.95 | AB20: =AB19 -> 2.6 | AC20: =AVERAGE(AW20:AX20)/1000 -> #VALUE! | AD20: =IF(AA20<-0.4,AB20*AC20,0) -> #VALUE! | AE20: =IF(AD20=0,0,E20) -> #VALUE! | AF20: =IFERROR(AE20-AD20,0) -> 0 | AG20: =AC20-AC19 -> #VALUE! | AH20: =IFERROR(AVERAGE(L16:L20)-AVERAGE(L21:L25),"-") -> - | AO20: =AVERAGE(P16:P20)-AVERAGE(P21:P25) -> 14.6 | AW20: =--MID(C20,FIND("від",C20)+4,FIND("грн",C20,FIND("від",C20))-FIND("від",C20)-4) -> 800000 | AX20: =--MID(C20,FIND("до",C20)+3,FIND("грн",C20,FIND("до",C20))-FIND("до",C20)-3) -> #VALUE!
A21: _I | B21: Тимчасове розмiщування й органiзацiя харчування | C21: від 850000 грн. до 899999,99 грн. | D21: 5 | E21: 4348.34 | F21: 11.8092 | G21: 0 | H21: 360 | I21: 314693.02 | J21: 4659.3997 | K21: 22.91 | P21: 74 | Q21: 64675.536 | R21: 2912.8015 | S21: 0 | T21: =AVERAGE(H17:H21)-AVERAGE(H22:H26) -> 4.4 | AA21: =IFERROR(AVERAGE(D17:D21)-AVERAGE(D22:D26),"-") -> -2 | AB21: =AB20 -> 2.6 | AC21: =AVERAGE(AW21:AX21)/1000 -> #VALUE! | AD21: =IF(AA21<-0.4,AB21*AC21,0) -> #VALUE! | AE21: =IF(AD21=0,0,E21) -> #VALUE! | AF21: =IFERROR(AE21-AD21,0) -> 0 | AG21: =AC21-AC20 -> #VALUE! | AH21: =IFERROR(AVERAGE(L17:L21)-AVERAGE(L22:L26),"-") -> 0 | AO21: =AVERAGE(P17:P21)-AVERAGE(P22:P26) -> 15.2 | AW21: =--MID(C21,FIND("від",C21)+4,FIND("грн",C21,FIND("від",C21))-FIND("від",C21)-4) -> 850000 | AX21: =--MID(C21,FIND("до",C21)+3,FIND("грн",C21,FIND("до",C21))-FIND("до",C21)-3) -> #VALUE!
A22: _I | B22: Тимчасове розмiщування й органiзацiя харчування | C22: від 900000 грн. до 949999,99 грн. | D22: 7 | E22: 6403.9551 | F22: 24.4046 | G22: 0.8 | H22: 402 | I22: 371459.69 | J22: 5264.7212 | K22: 20.96 | P22: 75 | Q22: 69336.854 | R22: 3105.6595 | S22: 0.8 | T22: =AVERAGE(H18:H22)-AVERAGE(H23:H27) -> 33.6 | AA22: =IFERROR(AVERAGE(D18:D22)-AVERAGE(D23:D27),"-") -> 0 | AB22: =AB21 -> 2.6 | AC22: =AVERAGE(AW22:AX22)/1000 -> #VALUE! | AD22: =IF(AA22<-0.4,AB22*AC22,0) -> 0 | AE22: =IF(AD22=0,0,E22) -> 0 | AF22: =IFERROR(AE22-AD22,0) -> 0 | AG22: =AC22-AC21 -> #VALUE! | AH22: =IFERROR(AVERAGE(L18:L22)-AVERAGE(L23:L27),"-") -> 0 | AO22: =AVERAGE(P18:P22)-AVERAGE(P23:P27) -> 14.2 | AW22: =--MID(C22,FIND("від",C22)+4,FIND("грн",C22,FIND("від",C22))-FIND("від",C22)-4) -> 900000 | AX22: =--MID(C22,FIND("до",C22)+3,FIND("грн",C22,FIND("до",C22))-FIND("до",C22)-3) -> #VALUE!
A23: _I | B23: Тимчасове розмiщування й органiзацiя харчування | C23: від 950000 грн. до 999999,99 грн. | D23: 8 | E23: 7843.142 | F23: 29.9678 | G23: 0 | H23: 368 | I23: 359051.63 | J23: 5013.2539 | K23: 28.155 | P23: 56 | Q23: 54660.296 | R23: 2220.3453 | S23: 0 | T23: =AVERAGE(H19:H23)-AVERAGE(H24:H28) -> 40 | AH23: =IFERROR(AVERAGE(L19:L23)-AVERAGE(L24:L28),"-") -> 0 | AO23: =AVERAGE(P19:P23)-AVERAGE(P24:P28) -> 6.6 | AW23: =--MID(C23,FIND("від",C23)+4,FIND("грн",C23,FIND("від",C23))-FIND("від",C23)-4) -> 950000 | AX23: =--MID(C23,FIND("до",C23)+3,FIND("грн",C23,FIND("до",C23))-FIND("до",C23)-3) -> #VALUE!
A24: _I | B24: Тимчасове розмiщування й органiзацiя харчування | C24: від 1000000 грн. до 1049999,99 грн. | H24: 345 | I24: 353356.05 | J24: 4679.4171 | K24: 23.71 | P24: 81 | Q24: 82790.331 | R24: 3512.0716 | S24: 0 | T24: =AVERAGE(H20:H24)-AVERAGE(H25:H29) -> 49.8 | AH24: =IFERROR(AVERAGE(L20:L24)-AVERAGE(L25:L29),"-") -> - | AO24: =AVERAGE(P20:P24)-AVERAGE(P25:P29) -> 13.2 | AW24: =--MID(C24,FIND("від",C24)+4,FIND("грн",C24,FIND("від",C24))-FIND("від",C24)-4) -> 1000000 | AX24: =--MID(C24,FIND("до",C24)+3,FIND("грн",C24,FIND("до",C24))-FIND("до",C24)-3) -> #VALUE!
A25: _I | B25: Тимчасове розмiщування й органiзацiя харчування | C25: від 1050000 грн. до 1099999,99 грн. | D25: 3 | E25: 3217.128 | F25: 10.13786 | G25: 0 | H25: 313 | I25: 336324.03 | J25: 4237.1272 | K25: 31.01 | P25: 64 | Q25: 69026.814 | R25: 3259.3953 | S25: 1.42 | T25: =AVERAGE(H21:H25)-AVERAGE(H26:H30) -> 46.6 | AH25: =IFERROR(AVERAGE(L21:L25)-AVERAGE(L26:L30),"-") -> - | AO25: =AVERAGE(P21:P25)-AVERAGE(P26:P30) -> 16.6 | AW25: =--MID(C25,FIND("від",C25)+4,FIND("грн",C25,FIND("від",C25))-FIND("від",C25)-4) -> 1050000 | AX25: =--MID(C25,FIND("до",C25)+3,FIND("грн",C25,FIND("до",C25))-FIND("до",C25)-3) -> #VALUE!
A26: _I | B26: Тимчасове розмiщування й органiзацiя харчування | C26: від 1100000 грн. до 1149999,99 грн. | D26: 2 | E26: 2235.5 | F26: 8.1188 | G26: 0 | H26: 341 | I26: 383475.59 | J26: 4764.1983 | K26: 16.96 | L26: 1 | M26: 1141.1272 | N26: 11.53383 | O26: 0 | P26: 54 | Q26: 60806.196 | R26: 2702.3168 | S26: 0 | T26: =AVERAGE(H22:H26)-AVERAGE(H27:H31) -> 49 | AH26: =IFERROR(AVERAGE(L22:L26)-AVERAGE(L27:L31),"-") -> 0 | AO26: =AVERAGE(P22:P26)-AVERAGE(P27:P31) -> 14.8 | AW26: =--MID(C26,FIND("від",C26)+4,FIND("грн",C26,FIND("від",C26))-FIND("від",C26)-4) -> 1100000 | AX26: =--MID(C26,FIND("до",C26)+3,FIND("грн",C26,FIND("до",C26))-FIND("до",C26)-3) -> #VALUE!
A27: _I | B27: Тимчасове розмiщування й органiзацiя харчування | C27: від 1150000 грн. до 1199999,99 грн. | D27: 3 | E27: 3503.008 | F27: 16.8704 | G27: 0 | H27: 302 | I27: 354721.79 | J27: 4110.7871 | K27: 21.04 | P27: 58 | Q27: 68063.925 | R27: 3627.4978 | S27: 0 | T27: =AVERAGE(H23:H27)-AVERAGE(H28:H32) -> 31 | AH27: =IFERROR(AVERAGE(L23:L27)-AVERAGE(L28:L32),"-") -> 0 | AO27: =AVERAGE(P23:P27)-AVERAGE(P28:P32) -> 14.2 | AW27: =--MID(C27,FIND("від",C27)+4,FIND("грн",C27,FIND("від",C27))-FIND("від",C27)-4) -> 1150000 | AX27: =--MID(C27,FIND("до",C27)+3,FIND("грн",C27,FIND("до",C27))-FIND("до",C27)-3) -> #VALUE!
A28: _I | B28: Тимчасове розмiщування й органiзацiя харчування | C28: від 1200000 грн. до 1249999,99 грн. | H28: 324 | I28: 396354.6 | J28: 4284.6953 | K28: 29.75 | P28: 55 | Q28: 67333.853 | R28: 2830.462 | S28: 0 | T28: =AVERAGE(H24:H28)-AVERAGE(H29:H33) -> 30.8 | AH28: =IFERROR(AVERAGE(L24:L28)-AVERAGE(L29:L33),"-") -> 0 | AO28: =AVERAGE(P24:P28)-AVERAGE(P29:P33) -> 17 | AW28: =--MID(C28,FIND("від",C28)+4,FIND("грн",C28,FIND("від",C28))-FIND("від",C28)-4) -> 1200000 | AX28: =--MID(C28,FIND("до",C28)+3,FIND("грн",C28,FIND("до",C28))-FIND("до",C28)-3) -> #VALUE!
A29: _I | B29: Тимчасове розмiщування й органiзацiя харчування | C29: від 1250000 грн. до 1299999,99 грн. | H29: 309 | I29: 393951.95 | J29: 4200.6011 | K29: 31.79 | L29: 1 | M29: 1265.9447 | N29: 34.5967 | O29: 0 | P29: 53 | Q29: 67588.011 | R29: 3004.9027 | S29: 0 | T29: =AVERAGE(H25:H29)-AVERAGE(H30:H34) -> 30.2 | AA29: =IFERROR(AVERAGE(D25:D29)-AVERAGE(D30:D34),"-") -> - | AH29: =IFERROR(AVERAGE(L25:L29)-AVERAGE(L30:L34),"-") -> 0 | AO29: =AVERAGE(P25:P29)-AVERAGE(P30:P34) -> 12.2 | AW29: =--MID(C29,FIND("від",C29)+4,FIND("грн",C29,FIND("від",C29))-FIND("від",C29)-4) -> 1250000 | AX29: =--MID(C29,FIND("до",C29)+3,FIND("грн",C29,FIND("до",C29))-FIND("до",C29)-3) -> #VALUE!
A30: _I | B30: Тимчасове розмiщування й органiзацiя харчування | C30: від 1300000 грн. до 1349999,99 грн. | H30: 279 | I30: 369834.16 | J30: 3763.41 | K30: 24.95 | P30: 47 | Q30: 62175.43 | R30: 2916.1147 | S30: 0 | T30: =AVERAGE(H26:H30)-AVERAGE(H31:H35) -> 25.6 | AA30: =IFERROR(AVERAGE(D26:D30)-AVERAGE(D31:D35),"-") -> - | AH30: =IFERROR(AVERAGE(L26:L30)-AVERAGE(L31:L35),"-") -> 0 | AO30: =AVERAGE(P26:P30)-AVERAGE(P31:P35) -> 12.2 | AW30: =--MID(C30,FIND("від",C30)+4,FIND("грн",C30,FIND("від",C30))-FIND("від",C30)-4) -> 1300000 | AX30: =--MID(C30,FIND("до",C30)+3,FIND("грн",C30,FIND("до",C30))-FIND("до",C30)-3) -> #VALUE!
A31: _I | B31: Тимчасове розмiщування й органiзацiя харчування | C31: від 1350000 грн. до 1399999,99 грн. | H31: 310 | I31: 426115.71 | J31: 4133.7579 | K31: 26.46 | L31: 1 | M31: 1383.1607 | N31: 72.94064 | O31: 0 | P31: 43 | Q31: 59044.51 | R31: 2620.4105 | S31: 0 | T31: =AVERAGE(H27:H31)-AVERAGE(H32:H36) -> 29.6 | AA31: =IFERROR(AVERAGE(D27:D31)-AVERAGE(D32:D36),"-") -> - | AH31: =IFERROR(AVERAGE(L27:L31)-AVERAGE(L32:L36),"-") -> 0 | AO31: =AVERAGE(P27:P31)-AVERAGE(P32:P36) -> 11.2 | AW31: =--MID(C31,FIND("від",C31)+4,FIND("грн",C31,FIND("від",C31))-FIND("від",C31)-4) -> 1350000 | AX31: =--MID(C31,FIND("до",C31)+3,FIND("грн",C31,FIND("до",C31))-FIND("до",C31)-3) -> #VALUE!
A32: _I | B32: Тимчасове розмiщування й органiзацiя харчування | C32: від 1400000 грн. до 1449999,99 грн. | H32: 292 | I32: 416405.94 | J32: 4052.5322 | K32: 25.31 | P32: 44 | Q32: 62763.145 | R32: 3097.2167 | S32: 0 | T32: =AVERAGE(H28:H32)-AVERAGE(H33:H37) -> 30.4 | AA32: =IFERROR(AVERAGE(D28:D32)-AVERAGE(D33:D37),"-") -> - | AH32: =IFERROR(AVERAGE(L28:L32)-AVERAGE(L33:L37),"-") -> 0 | AO32: =AVERAGE(P28:P32)-AVERAGE(P33:P37) -> 10.4 | AW32: =--MID(C32,FIND("від",C32)+4,FIND("грн",C32,FIND("від",C32))-FIND("від",C32)-4) -> 1400000 | AX32: =--MID(C32,FIND("до",C32)+3,FIND("грн",C32,FIND("до",C32))-FIND("до",C32)-3) -> #VALUE!
A33: _I | B33: Тимчасове розмiщування й органiзацiя харчування | C33: від 1450000 грн. до 1499999,99 грн. | H33: 281 | I33: 414169.91 | J33: 3793.5357 | K33: 35.44 | P33: 40 | Q33: 59164.352 | R33: 2859.0254 | S33: 0 | T33: =AVERAGE(H29:H33)-AVERAGE(H34:H38) -> 25 | AA33: =IFERROR(AVERAGE(D29:D33)-AVERAGE(D34:D38),"-") -> - | AH33: =IFERROR(AVERAGE(L29:L33)-AVERAGE(L34:L38),"-") -> 0 | AO33: =AVERAGE(P29:P33)-AVERAGE(P34:P38) -> 8.2 | AW33: =--MID(C33,FIND("від",C33)+4,FIND("грн",C33,FIND("від",C33))-FIND("від",C33)-4) -> 1450000 | AX33: =--MID(C33,FIND("до",C33)+3,FIND("грн",C33,FIND("до",C33))-FIND("до",C33)-3) -> #VALUE!
A34: _I | B34: Тимчасове розмiщування й органiзацiя харчування | C34: від 1500000 грн. до 1549999,99 грн. | H34: 276 | I34: 420917.13 | J34: 3828.2883 | K34: 21.42 | L34: 1 | M34: 1546.4927 | N34: 45.52853 | O34: 0 | P34: 49 | Q34: 74645.909 | R34: 3032.8512 | S34: 0.71 | T34: =AVERAGE(H30:H34)-AVERAGE(H35:H39) -> 23.4 | AA34: =IFERROR(AVERAGE(D30:D34)-AVERAGE(D35:D39),"-") -> - | AH34: =IFERROR(AVERAGE(L30:L34)-AVERAGE(L35:L39),"-") -> 0 | AO34: =AVERAGE(P30:P34)-AVERAGE(P35:P39) -> 12.8 | AW34: =--MID(C34,FIND("від",C34)+4,FIND("грн",C34,FIND("від",C34))-FIND("від",C34)-4) -> 1500000 | AX34: =--MID(C34,FIND("до",C34)+3,FIND("грн",C34,FIND("до",C34))-FIND("до",C34)-3) -> #VALUE!
A35: _I | B35: Тимчасове розмiщування й органiзацiя харчування | C35: від 1550000 грн. до 1599999,99 грн. | H35: 268 | I35: 422213.81 | J35: 3701.2932 | K35: 20.25 | P35: 30 | Q35: 47117.36 | R35: 1931.4592 | S35: 0 | T35: =AVERAGE(H31:H35)-AVERAGE(H36:H40) -> 25.8 | AA35: =IFERROR(AVERAGE(D31:D35)-AVERAGE(D36:D40),"-") -> - | AH35: =IFERROR(AVERAGE(L31:L35)-AVERAGE(L36:L40),"-") -> 0 | AO35: =AVERAGE(P31:P35)-AVERAGE(P36:P40) -> 8.8 | AW35: =--MID(C35,FIND("від",C35)+4,FIND("грн",C35,FIND("від",C35))-FIND("від",C35)-4) -> 1550000 | AX35: =--MID(C35,FIND("до",C35)+3,FIND("грн",C35,FIND("до",C35))-FIND("до",C35)-3) -> #VALUE!
A36: _I | B36: Тимчасове розмiщування й органiзацiя харчування | C36: від 1600000 грн. до 1649999,99 грн. | H36: 259 | I36: 420476.72 | J36: 3752.7247 | K36: 25.75 | P36: 37 | Q36: 60188.291 | R36: 2399.9043 | S36: 0 | T36: =AVERAGE(H32:H36)-AVERAGE(H37:H41) -> 22.8 | AA36: =IFERROR(AVERAGE(D32:D36)-AVERAGE(D37:D41),"-") -> - | AH36: =IFERROR(AVERAGE(L32:L36)-AVERAGE(L37:L41),"-") -> 0 | AO36: =AVERAGE(P32:P36)-AVERAGE(P37:P41) -> 10.2 | AW36: =--MID(C36,FIND("від",C36)+4,FIND("грн",C36,FIND("від",C36))-FIND("від",C36)-4) -> 1600000 | AX36: =--MID(C36,FIND("до",C36)+3,FIND("грн",C36,FIND("до",C36))-FIND("до",C36)-3) -> #VALUE!
A37: _I | B37: Тимчасове розмiщування й органiзацiя харчування | C37: від 1650000 грн. до 1699999,99 грн. | H37: 278 | I37: 465705.98 | J37: 3760.2692 | K37: 24.945 | P37: 34 | Q37: 56933.887 | R37: 2802.9597 | S37: 0 | T37: =AVERAGE(H33:H37)-AVERAGE(H38:H42) -> 32.4 | AA37: =IFERROR(AVERAGE(D33:D37)-AVERAGE(D38:D42),"-") -> - | AH37: =IFERROR(AVERAGE(L33:L37)-AVERAGE(L38:L42),"-") -> 0 | AO37: =AVERAGE(P33:P37)-AVERAGE(P38:P42) -> 9.8 | AW37: =--MID(C37,FIND("від",C37)+4,FIND("грн",C37,FIND("від",C37))-FIND("від",C37)-4) -> 1650000 | AX37: =--MID(C37,FIND("до",C37)+3,FIND("грн",C37,FIND("до",C37))-FIND("до",C37)-3) -> #VALUE!
A38: _I | B38: Тимчасове розмiщування й органiзацiя харчування | C38: від 1700000 грн. до 1749999,99 грн. | H38: 265 | I38: 457125.89 | J38: 3544.7406 | K38: 23.89 | L38: 1 | M38: 1731.726 | N38: 67.232 | O38: 0 | P38: 36 | Q38: 62112.174 | R38: 2680.6224 | S38: 0 | T38: =AVERAGE(H34:H38)-AVERAGE(H39:H43) -> 36.8 | AA38: =IFERROR(AVERAGE(D34:D38)-AVERAGE(D39:D43),"-") -> - | AH38: =IFERROR(AVERAGE(L34:L38)-AVERAGE(L39:L43),"-") -> - | AO38: =AVERAGE(P34:P38)-AVERAGE(P39:P43) -> 10.4 | AW38: =--MID(C38,FIND("від",C38)+4,FIND("грн",C38,FIND("від",C38))-FIND("від",C38)-4) -> 1700000 | AX38: =--MID(C38,FIND("до",C38)+3,FIND("грн",C38,FIND("до",C38))-FIND("до",C38)-3) -> #VALUE!
A39: _I | B39: Тимчасове розмiщування й органiзацiя харчування | C39: від 1750000 грн. до 1799999,99 грн. | H39: 251 | I39: 445551.28 | J39: 3623.0635 | K39: 25.84 | P39: 22 | Q39: 39146.693 | R39: 1496.9347 | S39: 0 | T39: =AVERAGE(H35:H39)-AVERAGE(H40:H44) -> 43.4 | AA39: =IFERROR(AVERAGE(D35:D39)-AVERAGE(D40:D44),"-") -> - | AH39: =IFERROR(AVERAGE(L35:L39)-AVERAGE(L40:L44),"-") -> - | AO39: =AVERAGE(P35:P39)-AVERAGE(P40:P44) -> 2.6 | AW39: =--MID(C39,FIND("від",C39)+4,FIND("грн",C39,FIND("від",C39))-FIND("від",C39)-4) -> 1750000 | AX39: =--MID(C39,FIND("до",C39)+3,FIND("грн",C39,FIND("до",C39))-FIND("до",C39)-3) -> #VALUE!
A40: _I | B40: Тимчасове розмiщування й органiзацiя харчування | C40: від 1800000 грн. до 1849999,99 грн. | H40: 245 | I40: 446966.79 | J40: 3362.8038 | K40: 18.2 | P40: 33 | Q40: 60237.569 | R40: 2703.1936 | S40: 0 | T40: =AVERAGE(H36:H40)-AVERAGE(H41:H45) -> 41 | AA40: =IFERROR(AVERAGE(D36:D40)-AVERAGE(D41:D45),"-") -> - | AH40: =IFERROR(AVERAGE(L36:L40)-AVERAGE(L41:L45),"-") -> - | AO40: =AVERAGE(P36:P40)-AVERAGE(P41:P45) -> 4.4 | AW40: =--MID(C40,FIND("від",C40)+4,FIND("грн",C40,FIND("від",C40))-FIND("від",C40)-4) -> 1800000 | AX40: =--MID(C40,FIND("до",C40)+3,FIND("грн",C40,FIND("до",C40))-FIND("до",C40)-3) -> #VALUE!
...

Sheet Sheet2
A1: І група
A3: Інтервал обороту, млн грн | B3: Кількість ФОПів
A4: <0,05-0,1 | B4: =SUM(_I!D4:D5) -> 46
A5: 0,1-0,2 | B5: =SUM(_I!D6:D7) -> 23
A6: 0,2-0,3 | B6: =SUM(_I!D8:D9) -> 12
A7: 0,3-0,4 | B7: =SUM(_I!D10:D11) -> 6
A8: 0,4-0,5 | B8: =SUM(_I!D12:D13) -> 4
A9: 0,5-0,6 | B9: =SUM(_I!D14:D15) -> 6
A10: 0,6-0,7 | B10: =SUM(_I!D16:D17) -> 6
A11: 0,7-0,8 | B11: =SUM(_I!D18:D19) -> 6
A12: 0,8-0,9 | B12: =SUM(_I!D20:D21) -> 7
A13: 0,9-1 | B13: =SUM(_I!D22:D23) -> 15
A14: 1-1,1 | B14: =SUM(_I!D24:D25) -> 3
A15: 1,1-1,2 | B15: =SUM(_I!D26:D27) -> 5
A16: 1,2->1,3 | B16: =SUM(_I!D28:D197) -> 0
A19: ІI група
A21: Інтервал обороту, млн грн | B21: Кількість ФОПів
A22: <0,05-0,5 | B22: =SUM(_I!H4:H13) -> 8064
A23: 0,5-1 | B23: =SUM(_I!H14:H23) -> 3864
A24: 1-1,5 | B24: =SUM(_I!H24:H33) -> 3096
A25: 1,5-2 | B25: =SUM(_I!H34:H43) -> 2508
A26: 2-2,5 | B26: =SUM(_I!H44:H53) -> 2148
A27: 2,5-3 | B27: =SUM(_I!H54:H63) -> 2084
A28: 3-3,5 | B28: =SUM(_I!H64:H73) -> 1787
A29: 3,5-4 | B29: =SUM(_I!H74:H83) -> 1779
A30: 4-4,5 | B30: =SUM(_I!H84:H93) -> 1845
A31: 4,5-5 | B31: =SUM(_I!H94:H103) -> 2166
A32: 5-5,5 | B32: =SUM(_I!H104:H113) -> 3461
A33: 5,5-6 | B33: =SUM(_I!H114:H123) -> 8057
A34: 6-6,5 | B34: =SUM(_I!H124:H133) -> 177
A35: 6,5-7 | B35: =SUM(_I!H134:H143) -> 40
A36: 7-7,5 | B36: =SUM(_I!H144:H153) -> 11
A37: 7,5->8 | B37: =SUM(_I!H154:H197) -> 14
A40: ІII група. Платники ПДВ
A42: Інтервал обороту, млн грн | B42: Кількість ФОПів
A43: <0,05-0,5 | B43: =SUM(_I!L4:L13) -> 18
A44: 0,5-1 | B44: =SUM(_I!L14:L23) -> 1
A45: 1-1,5 | B45: =SUM(_I!L24:L33) -> 3
A46: 1,5-2 | B46: =SUM(_I!L34:L43) -> 2
A47: 2-2,5 | B47: =SUM(_I!L44:L53) -> 4
...
